Workbook

Sheet Scénarios
A1: Lucien — résultat mensuel avant impôt selon les hypothèses (€)
A2: Valeurs figées, calculées à partir de l'onglet Hypothèses. Pour rejouer un scénario, modifiez les cellules jaunes de cet onglet : le Prévisionnel se recalcule. L'onglet Lancement 3 mois donne la trésorerie des premiers mois.
A4: Scénario | B4: 1 000 abonnés | C4: 5 000 | D4: 20 000 | E4: 100 000 | F4: 500 000
A5: A — Solo / Duo / Tribu (30 / 50 / 20 %), hypothèses de base (Bridge au tarif public 1 €) | B5: 4278 | C5: 15710 | D5: 71859 | E5: 402294 | F5: 2251972
A6: B — même grille, Bridge négocié à 0,60 € par compte | B6: 4621 | C6: 17426 | D6: 78723 | E6: 436614 | F6: 2423572
A7: C — même grille, churn à 5 % par mois (pessimiste) | B7: 3878 | C7: 13710 | D7: 63859 | E7: 362294 | F7: 2051972
A8: D — même grille, 15 comptes gratuits par payant (conversion faible) | B8: 4068 | C8: 14660 | D8: 67659 | E8: 381294 | F8: 2146972
A9: E — pour mémoire : 4 € / 40 €, hypothèses de base | B9: -73 | C9: -6044 | D9: -15157 | E9: -32786 | F9: 76569
A11: Lecture
A12: Avec la grille Solo 6,90 € / Duo 9,90 € / Tribu 13,90 € (mélange 30 / 50 / 20 %), le prix moyen est ≈ 9,80 € TTC et il reste ≈ 7,20 € nets par abonné après TVA et Stripe, pour ≈ 1,90 € de coûts variables (dont Bridge, plus élevé en Tribu). Le modèle est positif à tous les paliers, y compris au tarif public de Bridge.
A13: Le seuil de rentabilité de chaque palier (couvrir l'équipe et le support prévus) est atteint avec 20 à 35 % des abonnés du palier.
A14: Un abonné vaut ≈ 240 € nets sur sa durée de vie à 3 % de churn : un coût d'acquisition jusqu'à 60 à 80 € reste rentable.
A15: Le gratuit coûte ≈ 2 centimes par compte et par mois (IA en modèle rapide au quota, stockage, push). 15 gratuits par payant restent supportables (scénario D).
A16: Le risque principal est le churn : à 5 % par mois (scénario C), la valeur d'un abonné baisse d'un tiers. La rétention (économies réellement constatées) est le vrai moteur.

Sheet Hypothèses
A1: Lucien — hypothèses du prévisionnel
A2: Cellules en bleu sur fond jaune : à modifier librement. Tout le reste se recalcule.
A4: REVENUS
A5: Solo (1 personne) — prix mensuel TTC (€) | B5: 6.9 | C5: Grille du 29/10/2026 ; annuel = 10 × mensuel (69 €)
A6: Duo (2 personnes) — prix mensuel TTC (€) | B6: 9.9 | C6: Annuel 99 €
A7: Tribu (jusqu'à 6 personnes) — prix mensuel TTC (€) | B7: 13.9 | C7: Annuel 139 €
A8: Part des abonnés en Solo | B8: 0.3 | C8: Hypothèse : personnes seules et parents isolés
A9: Part des abonnés en Tribu | B9: 0.2 | C9: Hypothèse : familles avec ados ou grands-parents connectés ; le reste est en Duo
A10: Prix mensuel TTC (€) | B10: =Hypothèses!$B$5*Hypothèses!$B$8+Hypothèses!$B$7*Hypothèses!$B$9+Hypothèses!$B$6*(1-Hypothèses!$B$8-Hypothèses!$B$9) | C10: Calculé : prix moyen pondéré par le mélange de formules
A11: Prix annuel TTC (€) | B11: =Hypothèses!$B$10*10 | C11: Calculé : 10 mois payés, 2 offerts
A12: Part des abonnés en formule annuelle | B12: 0.5 | C12: Hypothèse : moitié mensuel, moitié annuel
A13: TVA | B13: 0.2 | C13: Service numérique en France : 20 %
A14: Commission moyenne de paiement (Stripe), % du TTC | B14: 0.015 | C14: Cartes européennes ≈ 1,5 % + 0,25 € ; les stores (Apple/Google) prendraient 15 à 30 % : à éviter, paiement web
A15: Frais fixes par transaction (€) | B15: 0.25 | C15: Stripe, par paiement ; un abonné annuel paie 1 fois par an, un mensuel 12 fois
A16: Utilisateurs gratuits par abonné payant | B16: 8 | C16: Hypothèse de conversion ≈ 11 % (1 payant pour 9 comptes). À vérifier après lancement
A17: Churn mensuel des abonnés | B17: 0.03 | C17: 3 % par mois : ordre de grandeur des applis grand public bien notées
A18: COÛTS VARIABLES (par foyer et par mois)
A19: IA — extraction de documents, foyer payant (€) | B19: 0.05 | C19: ≈ 5 documents/mois : modèle rapide (Haiku ≈ 0,5 c) avec repli sur le modèle précis (Sonnet ≈ 2 c) pour 15 % des documents, + catégorisation bancaire + courriers
A20: IA — foyer gratuit (€) | B20: 0 | C20: Gratuit nu : lecture locale sans IA, pas d'import de relevés ni de banque. 0 € d'IA (NIDOU_IA_LECTURES_GRATUIT=0 ; un quota rouvrable plus tard reste plafonné par NIDOU_IA_PLAFOND_GRATUIT_EUR)
A21: Agrégation bancaire Bridge, par compte connecté (€) | B21: 1 | C21: Tarif public indicatif 0,5 à 2 € par compte et par mois ; à négocier au volume
A22: Part des abonnés qui connectent leur banque | B22: 0.6 | C22: Hypothèse
A23: Nombre de comptes connectés par foyer connecté | B23: =1.1*Hypothèses!$B$8+2*Hypothèses!$B$9+1.4*(1-Hypothèses!$B$8-Hypothèses!$B$9) | C23: Calculé : 1,1 compte en Solo, 1,4 en Duo (compte joint + un perso), 2 en Tribu
A24: Stockage et bande passante, tous foyers (€) | B24: 0.01 | C24: OVH Object Storage ≈ 0,01 €/Go ; 50 documents × 2 Mo = 0,1 Go par foyer
A25: Emails et notifications push (€) | B25: 0.02 | C25: Payants : push + email (Brevo). Gratuits : push seulement, donc ≈ 0 ; la moyenne tous foyers est surestimée ici par prudence
A26: Coût d'acquisition d'un abonné payant (€) | B26: 20 | C26: Mix parrainage + publicité (15 €) + le coût de l'essai inversé des inscrits non convertis (≈ 5 € par payant gagné, voir onglet Lancement) ; dépensé pour remplacer le churn
A27: COÛTS FIXES PAR PALIER (€ / mois)
A28: Abonnés payants (palier) | B28: 1000 | C28: 5000 | D28: 20000 | E28: 100000 | F28: 500000
A29: Hébergement OVH (serveurs, base, sauvegardes) | B29: 60 | C29: 180 | D29: 600 | E29: 2500 | F29: 9000 | H29: VPS puis instances Public Cloud + base managée ; France
A30: Équipe technique (salaires chargés) | B30: 0 | C30: 6000 | D30: 18000 | E30: 60000 | F30: 180000 | H30: 0 : fondateur + Claude ; puis 1, 3, 10, 30 personnes à 6 000 € chargés
A31: Support client | B31: 0 | C31: 2000 | D31: 7000 | E31: 28000 | F31: 100000 | H31: 0,5 puis 2, 8, 30 personnes à 3 500 € chargés ; 1 agent pour ~2 500 à 5 000 payants
A32: Juridique, comptable, assurance, banque | B32: 500 | C32: 1000 | D32: 2500 | E32: 8000 | F32: 20000 | H32: Expert-comptable, RGPD, CGV, RC pro
A33: Outils et licences (Stripe hors commissions, Brevo, monitoring, domaine) | B33: 100 | C33: 300 | D33: 800 | E33: 3000 | F33: 8000
A34: Marketing de marque (hors acquisition payante) | B34: 500 | C34: 2000 | D34: 8000 | E34: 40000 | F34: 150000 | H34: Contenu, RP, partenariats
A36: Sources : prix Stripe et Bridge d'après leurs grilles publiques (ordres de grandeur, à confirmer par devis) ; coûts IA estimés d'après la consommation du prototype ; salaires chargés France. Tous les autres chiffres sont des hypothèses de travail.

Sheet Lancement 3 mois
A1: Lucien — lancement : ce que coûtent les 3 premiers mois
A2: Cellules bleues sur fond jaune : modifiables. Hypothèses de coût unitaire reprises de l'onglet Hypothèses (vert).
A4: HYPOTHÈSES DE LANCEMENT
A5: Inscriptions nouvelles par mois | B5: 500 | C5: 1500 | D5: 4000 | F5: Liste d'attente, bouche-à-oreille, premiers partages ; sans publicité payante
A6: Part des inscrits qui convertissent en payant à la fin de l'essai | B6: 0.08 | C6: 0.08 | D6: 0.08 | F6: Essai inversé 15 jours sans carte, puis gratuit nu (sans IA ni banque) : 5 à 12 % selon les produits ; 8 % en hypothèse centrale
A7: Churn mensuel des payants | B7: 0.03 | C7: 0.03 | D7: 0.03
A8: Part des inscrits en essai qui connectent leur banque | B8: 0.5 | C8: 0.5 | D8: 0.5 | F8: Pendant l'essai, Bridge est ouvert : c'est le principal coût de l'essai
A9: Documents lus par l'IA pendant l'essai, par inscrit | B9: 8 | C9: 8 | D9: 8 | F9: Modèle rapide (0,5 c) ; 15 % repassent en modèle précis (2 c)
A10: Documents lus par l'IA par compte gratuit et par mois (après essai) | B10: 0 | C10: 0 | D10: 0 | F10: Gratuit nu : lecture locale sans IA, pas d'import de relevés ni de banque (NIDOU_IA_LECTURES_GRATUIT=0)
A11: Hébergement OVH | B11: 60 | C11: 60 | D11: 120 | F11: VPS puis une instance de plus au mois 3
A12: Juridique, comptable, assurance (dont dépôt INPI 190 € au mois 1) | B12: 900 | C12: 500 | D12: 500 | F12: Expert-comptable ~250 €/mois, RC pro, CGV/RGPD relus par un avocat (~1 500 € à prévoir une fois, non inclus)
A13: Outils (domaine, Brevo, monitoring, Stripe hors commissions) | B13: 100 | C13: 100 | D13: 150
A14: Marketing (contenu, visuels, petits partenariats) | B14: 300 | C14: 500 | D14: 1000 | F14: Pas de publicité payante avant une conversion mesurée
A15: Équipe (hors fondateur) | B15: 0 | C15: 0 | D15: 0 | F15: Le fondateur et Claude ; une première embauche n'est pas nécessaire avant ~5 000 payants
A17: COÛTS UNITAIRES (repris de l'onglet Hypothèses)
A18: Coût d'une lecture IA pendant l'essai (€) | B18: =0.85*0.005+0.15*0.02 | F18: 85 % modèle rapide à 0,5 c, 15 % modèle précis à 2 c
A19: Bridge par compte connecté et par mois (€) | B19: =Hypothèses!$B$21
A20: Comptes connectés par foyer | B20: =Hypothèses!$B$23
A21: Stockage et push par compte et par mois (€) | B21: =Hypothèses!$B$24 | F21: Push gratuit ; pas d'email sur le gratuit
A22: Revenu net par payant et par mois (€) | B22: =Prévisionnel!$B$14/Prévisionnel!$B$4 | F22: Après TVA et commissions Stripe
A23: Coût variable d'un payant par mois (€) | B23: =-Prévisionnel!$B$21/Prévisionnel!$B$4 | F23: IA, Bridge, stockage, emails
A25: MOIS | B25: Mois 1 | C25: Mois 2 | D25: Mois 3 | E25: Total 3 mois
A26: Inscriptions du mois | B26: =B5 | C26: =C5 | D26: =D5 | E26: =SUM(B26:D26)
A27: Comptes en essai (15 jours, plan Famille complet) | B27: =B26 | C27: =C26 | D27: =D26
A28: Nouveaux payants (conversion en fin d'essai) | B28: =ROUND(B26*B6,0) | C28: =ROUND(C26*C6,0) | D28: =ROUND(D26*D6,0) | E28: =SUM(B28:D28)
A29: Payants en fin de mois | B29: =B28 | C29: =ROUND(B29*(1-C7),0)+C28 | D29: =ROUND(C29*(1-D7),0)+D28
A30: Comptes gratuits actifs en fin de mois (après essai, non convertis) | B30: =B26-B28 | C30: =B30+C26-C28 | D30: =C30+D26-D28
A32: REVENUS
A33: Revenu net encaissé (payants moyens du mois × revenu net) | B33: =(B29-B28/2)*$B$22 | C33: =(C29-C28/2)*$B$22 | D33: =(D29-D28/2)*$B$22 | E33: =SUM(B33:D33)
A35: COÛTS VARIABLES
A36: IA pendant l'essai | B36: =-B27*B9*$B$18 | C36: =-C27*C9*$B$18 | D36: =-D27*D9*$B$18 | E36: =SUM(B36:D36)
A37: Bridge pendant l'essai (½ mois, part connectée) | B37: =-B27*B8*$B$20*$B$19*0.5 | C37: =-C27*C8*$B$20*$B$19*0.5 | D37: =-D27*D8*$B$20*$B$19*0.5 | E37: =SUM(B37:D37)
A38: Comptes gratuits (stockage + push ; IA à zéro) | B38: =-B30*(B10*0.005+$B$21) | C38: =-C30*(C10*0.005+$B$21) | D38: =-D30*(D10*0.005+$B$21) | E38: =SUM(B38:D38)
A39: Payants (IA, Bridge, stockage, emails) | B39: =-(B29-B28/2)*$B$23 | C39: =-(C29-C28/2)*$B$23 | D39: =-(D29-D28/2)*$B$23 | E39: =SUM(B39:D39)
A40: Total coûts variables | B40: =SUM(B36:B39) | C40: =SUM(C36:C39) | D40: =SUM(D36:D39) | E40: =SUM(B40:D40)
A42: COÛTS FIXES
A43: Hébergement OVH | B43: =-B11 | C43: =-C11 | D43: =-D11 | E43: =SUM(B43:D43)
A44: Juridique, comptable, assurance (dont dépôt INPI 190 € au mois 1) | B44: =-B12 | C44: =-C12 | D44: =-D12 | E44: =SUM(B44:D44)
A45: Outils (domaine, Brevo, monitoring, Stripe hors commissions) | B45: =-B13 | C45: =-C13 | D45: =-D13 | E45: =SUM(B45:D45)
A46: Marketing (contenu, visuels, petits partenariats) | B46: =-B14 | C46: =-C14 | D46: =-D14 | E46: =SUM(B46:D46)
...

Sheet Prévisionnel
A1: Lucien — compte de résultat mensuel par palier d'abonnés payants
A2: Régime de croisière à chaque palier (hors phase de lancement). Montants hors taxes, par mois.
A4: Abonnés payants | B4: =Hypothèses!B$28 | C4: =Hypothèses!C$28 | D4: =Hypothèses!D$28 | E4: =Hypothèses!E$28 | F4: =Hypothèses!F$28
A5: Comptes gratuits | B5: =B4*Hypothèses!$B$16 | C5: =C4*Hypothèses!$B$16 | D5: =D4*Hypothèses!$B$16 | E5: =E4*Hypothèses!$B$16 | F5: =F4*Hypothèses!$B$16
A6: Foyers au total | B6: =B4+B5 | C6: =C4+C5 | D6: =D4+D5 | E6: =E4+E5 | F6: =F4+F5
A8: REVENUS
A9: Revenu TTC moyen par abonné et par mois | B9: =(Hypothèses!$B$10*(1-Hypothèses!$B$12)+Hypothèses!$B$11/12*Hypothèses!$B$12) | C9: =(Hypothèses!$B$10*(1-Hypothèses!$B$12)+Hypothèses!$B$11/12*Hypothèses!$B$12) | D9: =(Hypothèses!$B$10*(1-Hypothèses!$B$12)+Hypothèses!$B$11/12*Hypothèses!$B$12) | E9: =(Hypothèses!$B$10*(1-Hypothèses!$B$12)+Hypothèses!$B$11/12*Hypothèses!$B$12) | F9: =(Hypothèses!$B$10*(1-Hypothèses!$B$12)+Hypothèses!$B$11/12*Hypothèses!$B$12)
A10: Chiffre d'affaires TTC | B10: =B4*B9 | C10: =C4*C9 | D10: =D4*D9 | E10: =E4*E9 | F10: =F4*F9
A11: TVA collectée | B11: =-B10*Hypothèses!$B$13/(1+Hypothèses!$B$13) | C11: =-C10*Hypothèses!$B$13/(1+Hypothèses!$B$13) | D11: =-D10*Hypothèses!$B$13/(1+Hypothèses!$B$13) | E11: =-E10*Hypothèses!$B$13/(1+Hypothèses!$B$13) | F11: =-F10*Hypothèses!$B$13/(1+Hypothèses!$B$13)
A12: Chiffre d'affaires HT | B12: =B10+B11 | C12: =C10+C11 | D12: =D10+D11 | E12: =E10+E11 | F12: =F10+F11
A13: Commissions de paiement | B13: =-(B10*Hypothèses!$B$14+B4*((1-Hypothèses!$B$12)*1+Hypothèses!$B$12/12)*Hypothèses!$B$15) | C13: =-(C10*Hypothèses!$B$14+C4*((1-Hypothèses!$B$12)*1+Hypothèses!$B$12/12)*Hypothèses!$B$15) | D13: =-(D10*Hypothèses!$B$14+D4*((1-Hypothèses!$B$12)*1+Hypothèses!$B$12/12)*Hypothèses!$B$15) | E13: =-(E10*Hypothèses!$B$14+E4*((1-Hypothèses!$B$12)*1+Hypothèses!$B$12/12)*Hypothèses!$B$15) | F13: =-(F10*Hypothèses!$B$14+F4*((1-Hypothèses!$B$12)*1+Hypothèses!$B$12/12)*Hypothèses!$B$15)
A14: Revenu net encaissé | B14: =B12+B13 | C14: =C12+C13 | D14: =D12+D13 | E14: =E12+E13 | F14: =F12+F13
A16: COÛTS VARIABLES
A17: IA (extraction, catégorisation, courriers) | B17: =-(B4*Hypothèses!$B$19+B5*Hypothèses!$B$20) | C17: =-(C4*Hypothèses!$B$19+C5*Hypothèses!$B$20) | D17: =-(D4*Hypothèses!$B$19+D5*Hypothèses!$B$20) | E17: =-(E4*Hypothèses!$B$19+E5*Hypothèses!$B$20) | F17: =-(F4*Hypothèses!$B$19+F5*Hypothèses!$B$20)
A18: Agrégation bancaire (Bridge) | B18: =-B4*Hypothèses!$B$22*Hypothèses!$B$23*Hypothèses!$B$21 | C18: =-C4*Hypothèses!$B$22*Hypothèses!$B$23*Hypothèses!$B$21 | D18: =-D4*Hypothèses!$B$22*Hypothèses!$B$23*Hypothèses!$B$21 | E18: =-E4*Hypothèses!$B$22*Hypothèses!$B$23*Hypothèses!$B$21 | F18: =-F4*Hypothèses!$B$22*Hypothèses!$B$23*Hypothèses!$B$21
A19: Stockage, emails, notifications | B19: =-B6*(Hypothèses!$B$24+Hypothèses!$B$25) | C19: =-C6*(Hypothèses!$B$24+Hypothèses!$B$25) | D19: =-D6*(Hypothèses!$B$24+Hypothèses!$B$25) | E19: =-E6*(Hypothèses!$B$24+Hypothèses!$B$25) | F19: =-F6*(Hypothèses!$B$24+Hypothèses!$B$25)
A20: Acquisition pour remplacer le churn | B20: =-B4*Hypothèses!$B$17*Hypothèses!$B$26 | C20: =-C4*Hypothèses!$B$17*Hypothèses!$B$26 | D20: =-D4*Hypothèses!$B$17*Hypothèses!$B$26 | E20: =-E4*Hypothèses!$B$17*Hypothèses!$B$26 | F20: =-F4*Hypothèses!$B$17*Hypothèses!$B$26
A21: Total coûts variables | B21: =SUM(B17:B20) | C21: =SUM(C17:C20) | D21: =SUM(D17:D20) | E21: =SUM(E17:E20) | F21: =SUM(F17:F20)
A22: Marge sur coûts variables | B22: =B14+B21 | C22: =C14+C21 | D22: =D14+D21 | E22: =E14+E21 | F22: =F14+F21
A23: Marge sur coûts variables, % du CA HT | B23: =IF(B12=0,0,B22/B12) | C23: =IF(C12=0,0,C22/C12) | D23: =IF(D12=0,0,D22/D12) | E23: =IF(E12=0,0,E22/E12) | F23: =IF(F12=0,0,F22/F12)
A25: COÛTS FIXES
A26: Hébergement OVH (serveurs, base, sauvegardes) | B26: =-Hypothèses!B$29 | C26: =-Hypothèses!C$29 | D26: =-Hypothèses!D$29 | E26: =-Hypothèses!E$29 | F26: =-Hypothèses!F$29
A27: Équipe technique (salaires chargés) | B27: =-Hypothèses!B$30 | C27: =-Hypothèses!C$30 | D27: =-Hypothèses!D$30 | E27: =-Hypothèses!E$30 | F27: =-Hypothèses!F$30
A28: Support client | B28: =-Hypothèses!B$31 | C28: =-Hypothèses!C$31 | D28: =-Hypothèses!D$31 | E28: =-Hypothèses!E$31 | F28: =-Hypothèses!F$31
A29: Juridique, comptable, assurance, banque | B29: =-Hypothèses!B$32 | C29: =-Hypothèses!C$32 | D29: =-Hypothèses!D$32 | E29: =-Hypothèses!E$32 | F29: =-Hypothèses!F$32
A30: Outils et licences (Stripe hors commissions, Brevo, monitoring, domaine) | B30: =-Hypothèses!B$33 | C30: =-Hypothèses!C$33 | D30: =-Hypothèses!D$33 | E30: =-Hypothèses!E$33 | F30: =-Hypothèses!F$33
A31: Marketing de marque (hors acquisition payante) | B31: =-Hypothèses!B$34 | C31: =-Hypothèses!C$34 | D31: =-Hypothèses!D$34 | E31: =-Hypothèses!E$34 | F31: =-Hypothèses!F$34
A32: Total coûts fixes | B32: =SUM(B26:B31) | C32: =SUM(C26:C31) | D32: =SUM(D26:D31) | E32: =SUM(E26:E31) | F32: =SUM(F26:F31)
A34: RÉSULTAT MENSUEL (avant impôt) | B34: =B22+B32 | C34: =C22+C32 | D34: =D22+D32 | E34: =E22+E32 | F34: =F22+F32
A35: Résultat annuel (×12) | B35: =B34*12 | C35: =C34*12 | D35: =D34*12 | E35: =E34*12 | F35: =F34*12
A36: Marge nette, % du CA HT | B36: =IF(B12=0,0,B34/B12) | C36: =IF(C12=0,0,C34/C12) | D36: =IF(D12=0,0,D34/D12) | E36: =IF(E12=0,0,E34/E12) | F36: =IF(F12=0,0,F34/F12)
A38: REPÈRES
A39: Revenu net par abonné et par mois | B39: =IF(B4=0,0,B14/B4) | C39: =IF(C4=0,0,C14/C4) | D39: =IF(D4=0,0,D14/D4) | E39: =IF(E4=0,0,E14/E4) | F39: =IF(F4=0,0,F14/F4)
A40: Coût variable par abonné et par mois | B40: =IF(B4=0,0,-B21/B4) | C40: =IF(C4=0,0,-C21/C4) | D40: =IF(D4=0,0,-D21/D4) | E40: =IF(E4=0,0,-E21/E4) | F40: =IF(F4=0,0,-F21/F4)
A41: Abonnés payants nécessaires pour couvrir les coûts fixes du palier | B41: =IF(B22=0,0,ROUNDUP(-B32/(B22/B4),0)) | C41: =IF(C22=0,0,ROUNDUP(-C32/(C22/C4),0)) | D41: =IF(D22=0,0,ROUNDUP(-D32/(D22/D4),0)) | E41: =IF(E22=0,0,ROUNDUP(-E32/(E22/E4),0)) | F41: =IF(F22=0,0,ROUNDUP(-F32/(F22/F4),0))
A42: Chiffre d'affaires annuel HT | B42: =B12*12 | C42: =C12*12 | D42: =D12*12 | E42: =E12*12 | F42: =F12*12
A43: Valeur d'un abonné sur sa durée de vie (revenu net / churn) | B43: =IF(Hypothèses!$B$17=0,0,B14/B4/Hypothèses!$B$17) | C43: =IF(Hypothèses!$B$17=0,0,C14/C4/Hypothèses!$B$17) | D43: =IF(Hypothèses!$B$17=0,0,D14/D4/Hypothèses!$B$17) | E43: =IF(Hypothèses!$B$17=0,0,E14/E4/Hypothèses!$B$17) | F43: =IF(Hypothèses!$B$17=0,0,F14/F4/Hypothèses!$B$17)
A45: Lecture : chaque colonne est un palier atteint, en régime stable. Les coûts fixes par palier sont des choix d'organisation (équipe, support) ; les faire varier dans l'onglet Hypothèses déplace immédiatement le seuil de rentabilité.
