Workbook

Sheet Scénarios
A1: Nidou — résultat mensuel avant impôt selon les hypothèses (€)
A2: Valeurs figées, calculées à partir de l'onglet Hypothèses. Pour rejouer un scénario, modifiez les cellules jaunes de cet onglet : le Prévisionnel se recalcule. L'onglet Lancement 3 mois donne la trésorerie des premiers mois.
A4: Scénario | B4: 1 000 abonnés | C4: 5 000 | D4: 20 000 | E4: 100 000 | F4: 500 000
A5: A — 9,90 € / mois, 99 € / an, hypothèses de base (Bridge au tarif public 1 €) | B5: 4431 | C5: 16475 | D5: 74919 | E5: 417596 | F5: 2328479
A6: B — 9,90 € / 99 €, Bridge négocié à 0,60 € par compte | B6: 4743 | C6: 18035 | D6: 81159 | E6: 448796 | F6: 2484479
A7: C — 9,90 € / 99 €, churn à 5 % par mois (pessimiste) | B7: 4031 | C7: 14475 | D7: 66919 | E7: 377596 | F7: 2128479
A8: D — 9,90 € / 99 €, 15 comptes gratuits par payant (conversion faible) | B8: 4221 | C8: 15425 | D8: 70719 | E8: 396596 | F8: 2223479
A9: E — pour mémoire : 4 € / 40 €, hypothèses de base | B9: 5 | C9: -5654 | D9: -13597 | E9: -24986 | F9: 115569
A11: Lecture
A12: À 9,90 € TTC (99 € par an), il reste ≈ 7,30 € nets par abonné après TVA et Stripe, pour ≈ 1,80 € de coûts variables (dont Bridge 0,78 €). Le modèle est positif à tous les paliers, y compris au tarif public de Bridge.
A13: Le seuil de rentabilité de chaque palier (couvrir l'équipe et le support prévus) est atteint avec 20 à 35 % des abonnés du palier.
A14: Un abonné vaut ≈ 240 € nets sur sa durée de vie à 3 % de churn : un coût d'acquisition jusqu'à 60 à 80 € reste rentable.
A15: Le gratuit coûte ≈ 2 centimes par compte et par mois (IA en modèle rapide au quota, stockage, push). 15 gratuits par payant restent supportables (scénario D).
A16: Le risque principal est le churn : à 5 % par mois (scénario C), la valeur d'un abonné baisse d'un tiers. La rétention (économies réellement constatées) est le vrai moteur.

Sheet Hypothèses
A1: Nidou — hypothèses du prévisionnel
A2: Cellules en bleu sur fond jaune : à modifier librement. Tout le reste se recalcule.
A4: REVENUS
A5: Prix mensuel TTC (€) | B5: 9.9 | C5: Plan Famille, décision du 28/10/2026
A6: Prix annuel TTC (€) | B6: 99 | C6: Plan Famille, décision du 28/10/2026
A7: Part des abonnés en formule annuelle | B7: 0.5 | C7: Hypothèse : moitié mensuel, moitié annuel
A8: TVA | B8: 0.2 | C8: Service numérique en France : 20 %
A9: Commission moyenne de paiement (Stripe), % du TTC | B9: 0.015 | C9: Cartes européennes ≈ 1,5 % + 0,25 € ; les stores (Apple/Google) prendraient 15 à 30 % : à éviter, paiement web
A10: Frais fixes par transaction (€) | B10: 0.25 | C10: Stripe, par paiement ; un abonné annuel paie 1 fois par an, un mensuel 12 fois
A11: Utilisateurs gratuits par abonné payant | B11: 8 | C11: Hypothèse de conversion ≈ 11 % (1 payant pour 9 comptes). À vérifier après lancement
A12: Churn mensuel des abonnés | B12: 0.03 | C12: 3 % par mois : ordre de grandeur des applis grand public bien notées
A13: COÛTS VARIABLES (par foyer et par mois)
A14: IA — extraction de documents, foyer payant (€) | B14: 0.05 | C14: ≈ 5 documents/mois : modèle rapide (Haiku ≈ 0,5 c) avec repli sur le modèle précis (Sonnet ≈ 2 c) pour 15 % des documents, + catégorisation bancaire + courriers
A15: IA — foyer gratuit (€) | B15: 0 | C15: Gratuit nu : lecture locale sans IA, pas d'import de relevés ni de banque. 0 € d'IA (NIDOU_IA_LECTURES_GRATUIT=0 ; un quota rouvrable plus tard reste plafonné par NIDOU_IA_PLAFOND_GRATUIT_EUR)
A16: Agrégation bancaire Bridge, par compte connecté (€) | B16: 1 | C16: Tarif public indicatif 0,5 à 2 € par compte et par mois ; à négocier au volume
A17: Part des abonnés qui connectent leur banque | B17: 0.6 | C17: Hypothèse
A18: Nombre de comptes connectés par foyer connecté | B18: 1.3 | C18: Compte joint + un compte perso
A19: Stockage et bande passante, tous foyers (€) | B19: 0.01 | C19: OVH Object Storage ≈ 0,01 €/Go ; 50 documents × 2 Mo = 0,1 Go par foyer
A20: Emails et notifications push (€) | B20: 0.02 | C20: Payants : push + email (Brevo). Gratuits : push seulement, donc ≈ 0 ; la moyenne tous foyers est surestimée ici par prudence
A21: Coût d'acquisition d'un abonné payant (€) | B21: 20 | C21: Mix parrainage + publicité (15 €) + le coût de l'essai inversé des inscrits non convertis (≈ 5 € par payant gagné, voir onglet Lancement) ; dépensé pour remplacer le churn
A22: COÛTS FIXES PAR PALIER (€ / mois)
A23: Abonnés payants (palier) | B23: 1000 | C23: 5000 | D23: 20000 | E23: 100000 | F23: 500000
A24: Hébergement OVH (serveurs, base, sauvegardes) | B24: 60 | C24: 180 | D24: 600 | E24: 2500 | F24: 9000 | H24: VPS puis instances Public Cloud + base managée ; France
A25: Équipe technique (salaires chargés) | B25: 0 | C25: 6000 | D25: 18000 | E25: 60000 | F25: 180000 | H25: 0 : fondateur + Claude ; puis 1, 3, 10, 30 personnes à 6 000 € chargés
A26: Support client | B26: 0 | C26: 2000 | D26: 7000 | E26: 28000 | F26: 100000 | H26: 0,5 puis 2, 8, 30 personnes à 3 500 € chargés ; 1 agent pour ~2 500 à 5 000 payants
A27: Juridique, comptable, assurance, banque | B27: 500 | C27: 1000 | D27: 2500 | E27: 8000 | F27: 20000 | H27: Expert-comptable, RGPD, CGV, RC pro
A28: Outils et licences (Stripe hors commissions, Brevo, monitoring, domaine) | B28: 100 | C28: 300 | D28: 800 | E28: 3000 | F28: 8000
A29: Marketing de marque (hors acquisition payante) | B29: 500 | C29: 2000 | D29: 8000 | E29: 40000 | F29: 150000 | H29: Contenu, RP, partenariats
A31: Sources : prix Stripe et Bridge d'après leurs grilles publiques (ordres de grandeur, à confirmer par devis) ; coûts IA estimés d'après la consommation du prototype ; salaires chargés France. Tous les autres chiffres sont des hypothèses de travail.

Sheet Lancement 3 mois
A1: Nidou — lancement : ce que coûtent les 3 premiers mois
A2: Cellules bleues sur fond jaune : modifiables. Hypothèses de coût unitaire reprises de l'onglet Hypothèses (vert).
A4: HYPOTHÈSES DE LANCEMENT
A5: Inscriptions nouvelles par mois | B5: 500 | C5: 1500 | D5: 4000 | F5: Liste d'attente, bouche-à-oreille, premiers partages ; sans publicité payante
A6: Part des inscrits qui convertissent en payant à la fin de l'essai | B6: 0.08 | C6: 0.08 | D6: 0.08 | F6: Essai inversé 15 jours sans carte, puis gratuit nu (sans IA ni banque) : 5 à 12 % selon les produits ; 8 % en hypothèse centrale
A7: Churn mensuel des payants | B7: 0.03 | C7: 0.03 | D7: 0.03
A8: Part des inscrits en essai qui connectent leur banque | B8: 0.5 | C8: 0.5 | D8: 0.5 | F8: Pendant l'essai, Bridge est ouvert : c'est le principal coût de l'essai
A9: Documents lus par l'IA pendant l'essai, par inscrit | B9: 8 | C9: 8 | D9: 8 | F9: Modèle rapide (0,5 c) ; 15 % repassent en modèle précis (2 c)
A10: Documents lus par l'IA par compte gratuit et par mois (après essai) | B10: 0 | C10: 0 | D10: 0 | F10: Gratuit nu : lecture locale sans IA, pas d'import de relevés ni de banque (NIDOU_IA_LECTURES_GRATUIT=0)
A11: Hébergement OVH | B11: 60 | C11: 60 | D11: 120 | F11: VPS puis une instance de plus au mois 3
A12: Juridique, comptable, assurance (dont dépôt INPI 190 € au mois 1) | B12: 900 | C12: 500 | D12: 500 | F12: Expert-comptable ~250 €/mois, RC pro, CGV/RGPD relus par un avocat (~1 500 € à prévoir une fois, non inclus)
A13: Outils (domaine, Brevo, monitoring, Stripe hors commissions) | B13: 100 | C13: 100 | D13: 150
A14: Marketing (contenu, visuels, petits partenariats) | B14: 300 | C14: 500 | D14: 1000 | F14: Pas de publicité payante avant une conversion mesurée
A15: Équipe (hors fondateur) | B15: 0 | C15: 0 | D15: 0 | F15: Le fondateur et Claude ; une première embauche n'est pas nécessaire avant ~5 000 payants
A17: COÛTS UNITAIRES (repris de l'onglet Hypothèses)
A18: Coût d'une lecture IA pendant l'essai (€) | B18: =0.85*0.005+0.15*0.02 -> 0.00725 | F18: 85 % modèle rapide à 0,5 c, 15 % modèle précis à 2 c
A19: Bridge par compte connecté et par mois (€) | B19: =Hypothèses!$B$16 -> 1
A20: Comptes connectés par foyer | B20: =Hypothèses!$B$18 -> 1.3
A21: Stockage et push par compte et par mois (€) | B21: =Hypothèses!$B$19 -> 0.01 | F21: Push gratuit ; pas d'email sur le gratuit
A22: Revenu net par payant et par mois (€) | B22: =Prévisionnel!$B$14/Prévisionnel!$B$4 -> 7.2909583 | F22: Après TVA et commissions Stripe
A23: Coût variable d'un payant par mois (€) | B23: =-Prévisionnel!$B$21/Prévisionnel!$B$4 -> 1.7 | F23: IA, Bridge, stockage, emails
A25: MOIS | B25: Mois 1 | C25: Mois 2 | D25: Mois 3 | E25: Total 3 mois
A26: Inscriptions du mois | B26: =B5 -> 500 | C26: =C5 -> 1500 | D26: =D5 -> 4000 | E26: =SUM(B26:D26) -> 6000
A27: Comptes en essai (15 jours, plan Famille complet) | B27: =B26 -> 500 | C27: =C26 -> 1500 | D27: =D26 -> 4000
A28: Nouveaux payants (conversion en fin d'essai) | B28: =ROUND(B26*B6,0) -> 40 | C28: =ROUND(C26*C6,0) -> 120 | D28: =ROUND(D26*D6,0) -> 320 | E28: =SUM(B28:D28) -> 480
A29: Payants en fin de mois | B29: =B28 -> 40 | C29: =ROUND(B29*(1-C7),0)+C28 -> 159 | D29: =ROUND(C29*(1-D7),0)+D28 -> 474
A30: Comptes gratuits actifs en fin de mois (après essai, non convertis) | B30: =B26-B28 -> 460 | C30: =B30+C26-C28 -> 1840 | D30: =C30+D26-D28 -> 5520
A32: REVENUS
A33: Revenu net encaissé (payants moyens du mois × revenu net) | B33: =(B29-B28/2)*$B$22 -> 145.81917 | C33: =(C29-C28/2)*$B$22 -> 721.80488 | D33: =(D29-D28/2)*$B$22 -> 2289.3609 | E33: =SUM(B33:D33) -> 3156.985
A35: COÛTS VARIABLES
A36: IA pendant l'essai | B36: =-B27*B9*$B$18 -> -29 | C36: =-C27*C9*$B$18 -> -87 | D36: =-D27*D9*$B$18 -> -232 | E36: =SUM(B36:D36) -> -348
A37: Bridge pendant l'essai (½ mois, part connectée) | B37: =-B27*B8*$B$20*$B$19*0.5 -> -162.5 | C37: =-C27*C8*$B$20*$B$19*0.5 -> -487.5 | D37: =-D27*D8*$B$20*$B$19*0.5 -> -1300 | E37: =SUM(B37:D37) -> -1950
A38: Comptes gratuits (stockage + push ; IA à zéro) | B38: =-B30*(B10*0.005+$B$21) -> -4.6 | C38: =-C30*(C10*0.005+$B$21) -> -18.4 | D38: =-D30*(D10*0.005+$B$21) -> -55.2 | E38: =SUM(B38:D38) -> -78.2
A39: Payants (IA, Bridge, stockage, emails) | B39: =-(B29-B28/2)*$B$23 -> -34 | C39: =-(C29-C28/2)*$B$23 -> -168.3 | D39: =-(D29-D28/2)*$B$23 -> -533.8 | E39: =SUM(B39:D39) -> -736.1
A40: Total coûts variables | B40: =SUM(B36:B39) -> -230.1 | C40: =SUM(C36:C39) -> -761.2 | D40: =SUM(D36:D39) -> -2121 | E40: =SUM(B40:D40) -> -3112.3
A42: COÛTS FIXES
A43: Hébergement OVH | B43: =-B11 -> -60 | C43: =-C11 -> -60 | D43: =-D11 -> -120 | E43: =SUM(B43:D43) -> -240
A44: Juridique, comptable, assurance (dont dépôt INPI 190 € au mois 1) | B44: =-B12 -> -900 | C44: =-C12 -> -500 | D44: =-D12 -> -500 | E44: =SUM(B44:D44) -> -1900
A45: Outils (domaine, Brevo, monitoring, Stripe hors commissions) | B45: =-B13 -> -100 | C45: =-C13 -> -100 | D45: =-D13 -> -150 | E45: =SUM(B45:D45) -> -350
A46: Marketing (contenu, visuels, petits partenariats) | B46: =-B14 -> -300 | C46: =-C14 -> -500 | D46: =-D14 -> -1000 | E46: =SUM(B46:D46) -> -1800
...

Sheet Prévisionnel
A1: Nidou — compte de résultat mensuel par palier d'abonnés payants
A2: Régime de croisière à chaque palier (hors phase de lancement). Montants hors taxes, par mois.
A4: Abonnés payants | B4: =Hypothèses!B$23 -> 1000 | C4: =Hypothèses!C$23 -> 5000 | D4: =Hypothèses!D$23 -> 20000 | E4: =Hypothèses!E$23 -> 100000 | F4: =Hypothèses!F$23 -> 500000
A5: Comptes gratuits | B5: =B4*Hypothèses!$B$11 -> 8000 | C5: =C4*Hypothèses!$B$11 -> 40000 | D5: =D4*Hypothèses!$B$11 -> 160000 | E5: =E4*Hypothèses!$B$11 -> 800000 | F5: =F4*Hypothèses!$B$11 -> 4000000
A6: Foyers au total | B6: =B4+B5 -> 9000 | C6: =C4+C5 -> 45000 | D6: =D4+D5 -> 180000 | E6: =E4+E5 -> 900000 | F6: =F4+F5 -> 4500000
A8: REVENUS
A9: Revenu TTC moyen par abonné et par mois | B9: =(Hypothèses!$B$5*(1-Hypothèses!$B$7)+Hypothèses!$B$6/12*Hypothèses!$B$7) -> 9.075 | C9: =(Hypothèses!$B$5*(1-Hypothèses!$B$7)+Hypothèses!$B$6/12*Hypothèses!$B$7) -> 9.075 | D9: =(Hypothèses!$B$5*(1-Hypothèses!$B$7)+Hypothèses!$B$6/12*Hypothèses!$B$7) -> 9.075 | E9: =(Hypothèses!$B$5*(1-Hypothèses!$B$7)+Hypothèses!$B$6/12*Hypothèses!$B$7) -> 9.075 | F9: =(Hypothèses!$B$5*(1-Hypothèses!$B$7)+Hypothèses!$B$6/12*Hypothèses!$B$7) -> 9.075
A10: Chiffre d'affaires TTC | B10: =B4*B9 -> 9075 | C10: =C4*C9 -> 45375 | D10: =D4*D9 -> 181500 | E10: =E4*E9 -> 907500 | F10: =F4*F9 -> 4537500
A11: TVA collectée | B11: =-B10*Hypothèses!$B$8/(1+Hypothèses!$B$8) -> -1512.5 | C11: =-C10*Hypothèses!$B$8/(1+Hypothèses!$B$8) -> -7562.5 | D11: =-D10*Hypothèses!$B$8/(1+Hypothèses!$B$8) -> -30250 | E11: =-E10*Hypothèses!$B$8/(1+Hypothèses!$B$8) -> -151250 | F11: =-F10*Hypothèses!$B$8/(1+Hypothèses!$B$8) -> -756250
A12: Chiffre d'affaires HT | B12: =B10+B11 -> 7562.5 | C12: =C10+C11 -> 37812.5 | D12: =D10+D11 -> 151250 | E12: =E10+E11 -> 756250 | F12: =F10+F11 -> 3781250
A13: Commissions de paiement | B13: =-(B10*Hypothèses!$B$9+B4*((1-Hypothèses!$B$7)*1+Hypothèses!$B$7/12)*Hypothèses!$B$10) -> -271.54167 | C13: =-(C10*Hypothèses!$B$9+C4*((1-Hypothèses!$B$7)*1+Hypothèses!$B$7/12)*Hypothèses!$B$10) -> -1357.7083 | D13: =-(D10*Hypothèses!$B$9+D4*((1-Hypothèses!$B$7)*1+Hypothèses!$B$7/12)*Hypothèses!$B$10) -> -5430.8333 | E13: =-(E10*Hypothèses!$B$9+E4*((1-Hypothèses!$B$7)*1+Hypothèses!$B$7/12)*Hypothèses!$B$10) -> -27154.167 | F13: =-(F10*Hypothèses!$B$9+F4*((1-Hypothèses!$B$7)*1+Hypothèses!$B$7/12)*Hypothèses!$B$10) -> -135770.83
A14: Revenu net encaissé | B14: =B12+B13 -> 7290.9583 | C14: =C12+C13 -> 36454.792 | D14: =D12+D13 -> 145819.17 | E14: =E12+E13 -> 729095.83 | F14: =F12+F13 -> 3645479.2
A16: COÛTS VARIABLES
A17: IA (extraction, catégorisation, courriers) | B17: =-(B4*Hypothèses!$B$14+B5*Hypothèses!$B$15) -> -50 | C17: =-(C4*Hypothèses!$B$14+C5*Hypothèses!$B$15) -> -250 | D17: =-(D4*Hypothèses!$B$14+D5*Hypothèses!$B$15) -> -1000 | E17: =-(E4*Hypothèses!$B$14+E5*Hypothèses!$B$15) -> -5000 | F17: =-(F4*Hypothèses!$B$14+F5*Hypothèses!$B$15) -> -25000
A18: Agrégation bancaire (Bridge) | B18: =-B4*Hypothèses!$B$17*Hypothèses!$B$18*Hypothèses!$B$16 -> -780 | C18: =-C4*Hypothèses!$B$17*Hypothèses!$B$18*Hypothèses!$B$16 -> -3900 | D18: =-D4*Hypothèses!$B$17*Hypothèses!$B$18*Hypothèses!$B$16 -> -15600 | E18: =-E4*Hypothèses!$B$17*Hypothèses!$B$18*Hypothèses!$B$16 -> -78000 | F18: =-F4*Hypothèses!$B$17*Hypothèses!$B$18*Hypothèses!$B$16 -> -390000
A19: Stockage, emails, notifications | B19: =-B6*(Hypothèses!$B$19+Hypothèses!$B$20) -> -270 | C19: =-C6*(Hypothèses!$B$19+Hypothèses!$B$20) -> -1350 | D19: =-D6*(Hypothèses!$B$19+Hypothèses!$B$20) -> -5400 | E19: =-E6*(Hypothèses!$B$19+Hypothèses!$B$20) -> -27000 | F19: =-F6*(Hypothèses!$B$19+Hypothèses!$B$20) -> -135000
A20: Acquisition pour remplacer le churn | B20: =-B4*Hypothèses!$B$12*Hypothèses!$B$21 -> -600 | C20: =-C4*Hypothèses!$B$12*Hypothèses!$B$21 -> -3000 | D20: =-D4*Hypothèses!$B$12*Hypothèses!$B$21 -> -12000 | E20: =-E4*Hypothèses!$B$12*Hypothèses!$B$21 -> -60000 | F20: =-F4*Hypothèses!$B$12*Hypothèses!$B$21 -> -300000
A21: Total coûts variables | B21: =SUM(B17:B20) -> -1700 | C21: =SUM(C17:C20) -> -8500 | D21: =SUM(D17:D20) -> -34000 | E21: =SUM(E17:E20) -> -170000 | F21: =SUM(F17:F20) -> -850000
A22: Marge sur coûts variables | B22: =B14+B21 -> 5590.9583 | C22: =C14+C21 -> 27954.792 | D22: =D14+D21 -> 111819.17 | E22: =E14+E21 -> 559095.83 | F22: =F14+F21 -> 2795479.2
A23: Marge sur coûts variables, % du CA HT | B23: =IF(B12=0,0,B22/B12) -> 0.73930028 | C23: =IF(C12=0,0,C22/C12) -> 0.73930028 | D23: =IF(D12=0,0,D22/D12) -> 0.73930028 | E23: =IF(E12=0,0,E22/E12) -> 0.73930028 | F23: =IF(F12=0,0,F22/F12) -> 0.73930028
A25: COÛTS FIXES
A26: Hébergement OVH (serveurs, base, sauvegardes) | B26: =-Hypothèses!B$24 -> -60 | C26: =-Hypothèses!C$24 -> -180 | D26: =-Hypothèses!D$24 -> -600 | E26: =-Hypothèses!E$24 -> -2500 | F26: =-Hypothèses!F$24 -> -9000
A27: Équipe technique (salaires chargés) | B27: =-Hypothèses!B$25 -> 0 | C27: =-Hypothèses!C$25 -> -6000 | D27: =-Hypothèses!D$25 -> -18000 | E27: =-Hypothèses!E$25 -> -60000 | F27: =-Hypothèses!F$25 -> -180000
A28: Support client | B28: =-Hypothèses!B$26 -> 0 | C28: =-Hypothèses!C$26 -> -2000 | D28: =-Hypothèses!D$26 -> -7000 | E28: =-Hypothèses!E$26 -> -28000 | F28: =-Hypothèses!F$26 -> -100000
A29: Juridique, comptable, assurance, banque | B29: =-Hypothèses!B$27 -> -500 | C29: =-Hypothèses!C$27 -> -1000 | D29: =-Hypothèses!D$27 -> -2500 | E29: =-Hypothèses!E$27 -> -8000 | F29: =-Hypothèses!F$27 -> -20000
A30: Outils et licences (Stripe hors commissions, Brevo, monitoring, domaine) | B30: =-Hypothèses!B$28 -> -100 | C30: =-Hypothèses!C$28 -> -300 | D30: =-Hypothèses!D$28 -> -800 | E30: =-Hypothèses!E$28 -> -3000 | F30: =-Hypothèses!F$28 -> -8000
A31: Marketing de marque (hors acquisition payante) | B31: =-Hypothèses!B$29 -> -500 | C31: =-Hypothèses!C$29 -> -2000 | D31: =-Hypothèses!D$29 -> -8000 | E31: =-Hypothèses!E$29 -> -40000 | F31: =-Hypothèses!F$29 -> -150000
A32: Total coûts fixes | B32: =SUM(B26:B31) -> -1160 | C32: =SUM(C26:C31) -> -11480 | D32: =SUM(D26:D31) -> -36900 | E32: =SUM(E26:E31) -> -141500 | F32: =SUM(F26:F31) -> -467000
A34: RÉSULTAT MENSUEL (avant impôt) | B34: =B22+B32 -> 4430.9583 | C34: =C22+C32 -> 16474.792 | D34: =D22+D32 -> 74919.167 | E34: =E22+E32 -> 417595.83 | F34: =F22+F32 -> 2328479.2
A35: Résultat annuel (×12) | B35: =B34*12 -> 53171.5 | C35: =C34*12 -> 197697.5 | D35: =D34*12 -> 899030 | E35: =E34*12 -> 5011150 | F35: =F34*12 -> 27941750
A36: Marge nette, % du CA HT | B36: =IF(B12=0,0,B34/B12) -> 0.58591185 | C36: =IF(C12=0,0,C34/C12) -> 0.43569697 | D36: =IF(D12=0,0,D34/D12) -> 0.49533333 | E36: =IF(E12=0,0,E34/E12) -> 0.55219284 | F36: =IF(F12=0,0,F34/F12) -> 0.61579614
A38: REPÈRES
A39: Revenu net par abonné et par mois | B39: =IF(B4=0,0,B14/B4) -> 7.2909583 | C39: =IF(C4=0,0,C14/C4) -> 7.2909583 | D39: =IF(D4=0,0,D14/D4) -> 7.2909583 | E39: =IF(E4=0,0,E14/E4) -> 7.2909583 | F39: =IF(F4=0,0,F14/F4) -> 7.2909583
A40: Coût variable par abonné et par mois | B40: =IF(B4=0,0,-B21/B4) -> 1.7 | C40: =IF(C4=0,0,-C21/C4) -> 1.7 | D40: =IF(D4=0,0,-D21/D4) -> 1.7 | E40: =IF(E4=0,0,-E21/E4) -> 1.7 | F40: =IF(F4=0,0,-F21/F4) -> 1.7
A41: Abonnés payants nécessaires pour couvrir les coûts fixes du palier | B41: =IF(B22=0,0,ROUNDUP(-B32/(B22/B4),0)) -> 208 | C41: =IF(C22=0,0,ROUNDUP(-C32/(C22/C4),0)) -> 2054 | D41: =IF(D22=0,0,ROUNDUP(-D32/(D22/D4),0)) -> 6600 | E41: =IF(E22=0,0,ROUNDUP(-E32/(E22/E4),0)) -> 25309 | F41: =IF(F22=0,0,ROUNDUP(-F32/(F22/F4),0)) -> 83528
A42: Chiffre d'affaires annuel HT | B42: =B12*12 -> 90750 | C42: =C12*12 -> 453750 | D42: =D12*12 -> 1815000 | E42: =E12*12 -> 9075000 | F42: =F12*12 -> 45375000
A43: Valeur d'un abonné sur sa durée de vie (revenu net / churn) | B43: =IF(Hypothèses!$B$12=0,0,B14/B4/Hypothèses!$B$12) -> 243.03194 | C43: =IF(Hypothèses!$B$12=0,0,C14/C4/Hypothèses!$B$12) -> 243.03194 | D43: =IF(Hypothèses!$B$12=0,0,D14/D4/Hypothèses!$B$12) -> 243.03194 | E43: =IF(Hypothèses!$B$12=0,0,E14/E4/Hypothèses!$B$12) -> 243.03194 | F43: =IF(Hypothèses!$B$12=0,0,F14/F4/Hypothèses!$B$12) -> 243.03194
A45: Lecture : chaque colonne est un palier atteint, en régime stable. Les coûts fixes par palier sont des choix d'organisation (équipe, support) ; les faire varier dans l'onglet Hypothèses déplace immédiatement le seuil de rentabilité.
